{"uri":"file:///Users/vega/Code/huli/manager-web/src/vendor/phpunit/phpunit/src/Framework/TestFailure.php","root":{"kind":0,"name":"","children":[{"kind":1,"name":"PHPUnit_Framework_TestFailure","location":[13,0,160,1],"description":"A TestFailure collects a failed test together with the caught exception.","children":[{"kind":16,"name":"$testName","modifiers":4,"location":[18,12,18,21],"scope":"PHPUnit_Framework_TestFailure","type":"string"},{"kind":16,"name":"$failedTest","modifiers":2,"location":[23,14,23,25],"scope":"PHPUnit_Framework_TestFailure","type":"PHPUnit_Framework_Test|null"},{"kind":16,"name":"$thrownException","modifiers":2,"location":[28,14,28,30],"scope":"PHPUnit_Framework_TestFailure","type":"Exception"},{"kind":32,"name":"__construct","modifiers":1,"location":[36,4,49,5],"description":"Constructs a TestFailure with the given test and exception.","scope":"PHPUnit_Framework_TestFailure","children":[{"kind":128,"name":"$failedTest","location":[36,32,36,66],"scope":"__construct","typeSource":1,"type":"PHPUnit_Framework_Test"},{"kind":128,"name":"$t","location":[36,68,36,70],"scope":"__construct","type":"Throwable"}]},{"kind":32,"name":"toString","modifiers":1,"location":[56,4,63,5],"description":"Returns a short description of the failure.","scope":"PHPUnit_Framework_TestFailure","type":"string"},{"kind":32,"name":"getExceptionAsString","modifiers":1,"location":[70,4,73,5],"description":"Returns a description for the thrown exception.","scope":"PHPUnit_Framework_TestFailure","type":"string"},{"kind":32,"name":"exceptionToString","modifiers":33,"location":[82,4,103,5],"description":"Returns a description for an exception.","scope":"PHPUnit_Framework_TestFailure","type":"string","children":[{"kind":128,"name":"$e","location":[82,45,82,57],"scope":"exceptionToString","typeSource":1,"type":"Exception"}]},{"kind":32,"name":"getTestName","modifiers":1,"location":[110,4,113,5],"description":"Returns the name of the failing test (including data set, if any).","scope":"PHPUnit_Framework_TestFailure","type":"string"},{"kind":32,"name":"failedTest","modifiers":1,"location":[125,4,128,5],"description":"Returns the failing test.\n\nNote: The test object is not set when the test is executed in process\nisolation.","scope":"PHPUnit_Framework_TestFailure","type":"PHPUnit_Framework_Test|null"},{"kind":32,"name":"thrownException","modifiers":1,"location":[135,4,138,5],"description":"Gets the thrown exception.","scope":"PHPUnit_Framework_TestFailure","type":"Exception"},{"kind":32,"name":"exceptionMessage","modifiers":1,"location":[145,4,148,5],"description":"Returns the exception's message.","scope":"PHPUnit_Framework_TestFailure","type":"string"},{"kind":32,"name":"isFailure","modifiers":1,"location":[156,4,159,5],"description":"Returns true if the thrown exception\nis of type AssertionFailedError.","scope":"PHPUnit_Framework_TestFailure","type":"bool"}]}]}}